Execution failed. User process '/azureml-envs/azureml_950d58957dc3b9d216b75e5c20b0429c/bin/python' exited with status code 1. Please check log file 'user_logs/std_log.txt' for error details. Error: Traceback (most recent call last):
  File "<string>", line 197, in <module>
  File "<string>", line 193, in main
  File "/azureml-envs/azureml_950d58957dc3b9d216b75e5c20b0429c/lib/python3.8/runpy.py", line 264, in run_path
    code, fname = _get_code_from_file(run_name, path_name)
  File "/azureml-envs/azureml_950d58957dc3b9d216b75e5c20b0429c/lib/python3.8/runpy.py", line 234, in _get_code_from_file
    with io.open_code(decoded_path) as f:
FileNotFoundError: [Errno 2] No such file or directory: '/mnt/azureml/cr/j/708c7174a86d46ecb55bc5cc3d484c7f/exe/wd/train.py'

 Marking the experiment as failed because initial child jobs have failed due to user error
